<?xml version="1.0" ?>
<robot name="PRM_components_urdf" xmlns:xacro="http://www.ros.org/wiki/xacro">

<xacro:include filename="$(find PRM_components_urdf_description)/urdf/materials.xacro" />
<xacro:include filename="$(find PRM_components_urdf_description)/urdf/PRM_components_urdf.trans" />
<xacro:include filename="$(find PRM_components_urdf_description)/urdf/PRM_components_urdf.gazebo" />
<link name="base_link">
  <inertial>
    <origin rpy="0 0 0" xyz="-0.10577629127207062 0.005761505432528843 0.03808535197655524"/>
    <mass value="1.0594038588025692"/>
    <inertia ixx="0.001676" ixy="0.000152" ixz="0.000333" iyy="0.008771" iyz="-7.1e-05" izz="0.009683"/>
  </inertial>
  <visual>
    <origin rpy="0 0 0" xyz="0 0 0"/>
    <geometry>
      <mesh filename="package://PRM_components_urdf_description/meshes/base_link.stl" scale="0.001 0.001 0.001"/>
    </geometry>
    <material name="silver"/>
  </visual>
  <collision>
    <origin rpy="0 0 0" xyz="0 0 0"/>
    <geometry>
      <mesh filename="package://PRM_components_urdf_description/meshes/base_link.stl" scale="0.001 0.001 0.001"/>
    </geometry>
  </collision>
</link>

<link name="left_wheel_1">
  <inertial>
    <origin rpy="0 0 0" xyz="-5.514750903637747e-06 0.01684893311479653 7.516213665285931e-06"/>
    <mass value="0.0557255774837727"/>
    <inertia ixx="1.9e-05" ixy="0.0" ixz="0.0" iyy="3e-05" iyz="-0.0" izz="1.9e-05"/>
  </inertial>
  <visual>
    <origin rpy="0 0 0" xyz="0.010889 -0.058419 -0.032408"/>
    <geometry>
      <mesh filename="package://PRM_components_urdf_description/meshes/left_wheel_1.stl" scale="0.001 0.001 0.001"/>
    </geometry>
    <material name="silver"/>
  </visual>
  <collision>
    <origin rpy="0 0 0" xyz="0.010889 -0.058419 -0.032408"/>
    <geometry>
      <mesh filename="package://PRM_components_urdf_description/meshes/left_wheel_1.stl" scale="0.001 0.001 0.001"/>
    </geometry>
  </collision>
</link>

<link name="right_wheel_3">
  <inertial>
    <origin rpy="0 0 0" xyz="6.825622156371794e-06 -0.0168397715083117 5.538351484139781e-06"/>
    <mass value="0.055725588971055603"/>
    <inertia ixx="1.9e-05" ixy="-0.0" ixz="-0.0" iyy="3e-05" iyz="-0.0" izz="1.9e-05"/>
  </inertial>
  <visual>
    <origin rpy="0 0 0" xyz="0.010889 0.051581 -0.032408"/>
    <geometry>
      <mesh filename="package://PRM_components_urdf_description/meshes/right_wheel_3.stl" scale="0.001 0.001 0.001"/>
    </geometry>
    <material name="silver"/>
  </visual>
  <collision>
    <origin rpy="0 0 0" xyz="0.010889 0.051581 -0.032408"/>
    <geometry>
      <mesh filename="package://PRM_components_urdf_description/meshes/right_wheel_3.stl" scale="0.001 0.001 0.001"/>
    </geometry>
  </collision>
</link>

<link name="lien_plaque_sup_1">
  <inertial>
    <origin rpy="0 0 0" xyz="-0.06000033725581454 -0.03999979892532527 0.030000328306584424"/>
    <mass value="0.016233798346575297"/>
    <inertia ixx="3.1e-05" ixy="0.0" ixz="0.0" iyy="6.3e-05" iyz="0.0" izz="8.4e-05"/>
  </inertial>
  <visual>
    <origin rpy="0 0 0" xyz="0.017389 -0.043419 -0.051408"/>
    <geometry>
      <mesh filename="package://PRM_components_urdf_description/meshes/lien_plaque_sup_1.stl" scale="0.001 0.001 0.001"/>
    </geometry>
    <material name="silver"/>
  </visual>
  <collision>
    <origin rpy="0 0 0" xyz="0.017389 -0.043419 -0.051408"/>
    <geometry>
      <mesh filename="package://PRM_components_urdf_description/meshes/lien_plaque_sup_1.stl" scale="0.001 0.001 0.001"/>
    </geometry>
  </collision>
</link>

<link name="plaque_sup_1">
  <inertial>
    <origin rpy="0 0 0" xyz="-0.06029791949219093 -0.03999979900860389 0.00604737283687512"/>
    <mass value="0.26145266960030816"/>
    <inertia ixx="0.000583" ixy="1e-06" ixz="-0.0" iyy="0.001267" iyz="0.0" izz="0.001836"/>
  </inertial>
  <visual>
    <origin rpy="0 0 0" xyz="0.017389 -0.043419 -0.111408"/>
    <geometry>
      <mesh filename="package://PRM_components_urdf_description/meshes/plaque_sup_1.stl" scale="0.001 0.001 0.001"/>
    </geometry>
    <material name="silver"/>
  </visual>
  <collision>
    <origin rpy="0 0 0" xyz="0.017389 -0.043419 -0.111408"/>
    <geometry>
      <mesh filename="package://PRM_components_urdf_description/meshes/plaque_sup_1.stl" scale="0.001 0.001 0.001"/>
    </geometry>
  </collision>
</link>

<link name="laser_1">
  <inertial>
    <origin rpy="0 0 0" xyz="0.03968835231768589 0.027497343099224456 0.022537081249719412"/>
    <mass value="0.07886865487875269"/>
    <inertia ixx="4e-05" ixy="-1e-06" ixz="6e-06" iyy="7.4e-05" iyz="0.0" izz="8.3e-05"/>
  </inertial>
  <visual>
    <origin rpy="0 0 0" xyz="0.138934 0.024581 -0.122908"/>
    <geometry>
      <mesh filename="package://PRM_components_urdf_description/meshes/laser_1.stl" scale="0.001 0.001 0.001"/>
    </geometry>
    <material name="silver"/>
  </visual>
  <collision>
    <origin rpy="0 0 0" xyz="0.138934 0.024581 -0.122908"/>
    <geometry>
      <mesh filename="package://PRM_components_urdf_description/meshes/laser_1.stl" scale="0.001 0.001 0.001"/>
    </geometry>
  </collision>
</link>

<link name="tilt_1">
  <inertial>
    <origin rpy="0 0 0" xyz="0.0037386169360073412 0.012530560104144628 0.008107618712737519"/>
    <mass value="0.0837710951291597"/>
    <inertia ixx="1.2e-05" ixy="0.0" ixz="-1e-06" iyy="9e-06" iyz="-0.0" izz="9e-06"/>
  </inertial>
  <visual>
    <origin rpy="0 0 0" xyz="-0.087561 0.006184 -0.082523"/>
    <geometry>
      <mesh filename="package://PRM_components_urdf_description/meshes/tilt_1.stl" scale="0.001 0.001 0.001"/>
    </geometry>
    <material name="silver"/>
  </visual>
  <collision>
    <origin rpy="0 0 0" xyz="-0.087561 0.006184 -0.082523"/>
    <geometry>
      <mesh filename="package://PRM_components_urdf_description/meshes/tilt_1.stl" scale="0.001 0.001 0.001"/>
    </geometry>
  </collision>
</link>

<link name="camera_1">
  <inertial>
    <origin rpy="0 0 0" xyz="0.0006061218390486928 -0.002779711025054816 3.853164737116499e-05"/>
    <mass value="0.0010901216474161416"/>
    <inertia ixx="0.0" ixy="-0.0" ixz="0.0" iyy="0.0" iyz="-0.0" izz="0.0"/>
  </inertial>
  <visual>
    <origin rpy="0 0 0" xyz="-0.108792 -0.005812 -0.094601"/>
    <geometry>
      <mesh filename="package://PRM_components_urdf_description/meshes/camera_1.stl" scale="0.001 0.001 0.001"/>
    </geometry>
    <material name="silver"/>
  </visual>
  <collision>
    <origin rpy="0 0 0" xyz="-0.108792 -0.005812 -0.094601"/>
    <geometry>
      <mesh filename="package://PRM_components_urdf_description/meshes/camera_1.stl" scale="0.001 0.001 0.001"/>
    </geometry>
  </collision>
</link>

<link name="pan_1">
  <inertial>
    <origin rpy="0 0 0" xyz="0.0069708218233762095 -0.00020090348207176673 0.01747484554716784"/>
    <mass value="0.10221097927434727"/>
    <inertia ixx="1.4e-05" ixy="0.0" ixz="-3e-06" iyy="1.7e-05" iyz="0.0" izz="1.9e-05"/>
  </inertial>
  <visual>
    <origin rpy="0 0 0" xyz="-0.060411 -0.003405 -0.048232"/>
    <geometry>
      <mesh filename="package://PRM_components_urdf_description/meshes/pan_1.stl" scale="0.001 0.001 0.001"/>
    </geometry>
    <material name="silver"/>
  </visual>
  <collision>
    <origin rpy="0 0 0" xyz="-0.060411 -0.003405 -0.048232"/>
    <geometry>
      <mesh filename="package://PRM_components_urdf_description/meshes/pan_1.stl" scale="0.001 0.001 0.001"/>
    </geometry>
  </collision>
</link>

<link name="roue_folle_1">
  <inertial>
    <origin rpy="0 0 0" xyz="-8.763853124593712e-07 6.426062275442096e-07 -0.0006014809640806466"/>
    <mass value="0.0034293258621157863"/>
    <inertia ixx="0.0" ixy="0.0" ixz="0.0" iyy="0.0" iyz="-0.0" izz="0.0"/>
  </inertial>
  <visual>
    <origin rpy="0 0 0" xyz="0.192139 -0.003419 -0.017908"/>
    <geometry>
      <mesh filename="package://PRM_components_urdf_description/meshes/roue_folle_1.stl" scale="0.001 0.001 0.001"/>
    </geometry>
    <material name="silver"/>
  </visual>
  <collision>
    <origin rpy="0 0 0" xyz="0.192139 -0.003419 -0.017908"/>
    <geometry>
      <mesh filename="package://PRM_components_urdf_description/meshes/roue_folle_1.stl" scale="0.001 0.001 0.001"/>
    </geometry>
  </collision>
</link>

<link name="bille_porteuse_1">
  <inertial>
    <origin rpy="0 0 0" xyz="-3.3564421661469446e-07 2.010746746159038e-07 3.283065864671114e-07"/>
    <mass value="0.008419367021437509"/>
    <inertia ixx="0.0" ixy="-0.0" ixz="0.0" iyy="0.0" iyz="0.0" izz="0.0"/>
  </inertial>
  <visual>
    <origin rpy="0 0 0" xyz="0.192139 -0.003419 -0.010511"/>
    <geometry>
      <mesh filename="package://PRM_components_urdf_description/meshes/bille_porteuse_1.stl" scale="0.001 0.001 0.001"/>
    </geometry>
    <material name="silver"/>
  </visual>
  <collision>
    <origin rpy="0 0 0" xyz="0.192139 -0.003419 -0.010511"/>
    <geometry>
      <mesh filename="package://PRM_components_urdf_description/meshes/bille_porteuse_1.stl" scale="0.001 0.001 0.001"/>
    </geometry>
  </collision>
</link>

<joint name="rev_left" type="continuous">
  <origin rpy="0 0 0" xyz="-0.010889 0.058419 0.032408"/>
  <parent link="base_link"/>
  <child link="left_wheel_1"/>
  <axis xyz="0.0 0.01 -0.0"/>
</joint>

<joint name="rev_right" type="continuous">
  <origin rpy="0 0 0" xyz="-0.010889 -0.051581 0.032408"/>
  <parent link="base_link"/>
  <child link="right_wheel_3"/>
  <axis xyz="-0.0 -0.01 0.0"/>
</joint>

<joint name="rigid_plaque_inf" type="fixed">
  <origin rpy="0 0 0" xyz="-0.017389 0.043419 0.051408"/>
  <parent link="base_link"/>
  <child link="lien_plaque_sup_1"/>
</joint>

<joint name="rigid_plaque_sup" type="fixed">
  <origin rpy="0 0 0" xyz="0.0 0.0 0.06"/>
  <parent link="lien_plaque_sup_1"/>
  <child link="plaque_sup_1"/>
</joint>

<joint name="rplidar_joint" type="fixed">
  <origin rpy="0 0 0" xyz="-0.121545 -0.068 0.0115"/>
  <parent link="plaque_sup_1"/>
  <child link="laser_1"/>
</joint>

<joint name="tilt_joint" type="revolute">
  <origin rpy="0 0 0" xyz="0.02715 -0.009589 0.034291"/>
  <parent link="pan_1"/>
  <child link="tilt_1"/>
  <axis xyz="5.3e-05 -0.01 -9e-06"/>
  <limit effort="100" lower="-1.434661" upper="1.434661" velocity="100"/>
</joint>

<joint name="rigid_camera" type="fixed">
  <origin rpy="0 0 0" xyz="0.021231 0.011996 0.012078"/>
  <parent link="tilt_1"/>
  <child link="camera_1"/>
</joint>

<joint name="pan_joint" type="continuous">
  <origin rpy="0 0 0" xyz="0.060411 0.003405 0.048232"/>
  <parent link="base_link"/>
  <child link="pan_1"/>
  <axis xyz="-0.0 -9e-06 0.01"/>
</joint>

<joint name="rigid_roue_folle" type="fixed">
  <origin rpy="0 0 0" xyz="-0.192139 0.003419 0.017908"/>
  <parent link="base_link"/>
  <child link="roue_folle_1"/>
</joint>

<joint name="caster" type="Ball">
  <origin rpy="0 0 0" xyz="0.0 0.0 -0.007397"/>
  <parent link="roue_folle_1"/>
  <child link="bille_porteuse_1"/>
</joint>

</robot>
